#VRML_SIM R2021a utf8
WorldInfo {
  coordinateSystem "NUE"
}
Viewpoint {
  orientation -0.3178817123794132 -0.9190947307657847 -0.2328434942473198 1.3715151683342477
  position -0.8888358248857935 0.5127881891361222 0.15699381273084684
}
TexturedBackground {
}
TexturedBackgroundLight {
}
RectangleArena {
}
Robot {
  translation 0 0.06 -0.08
  scale 0.5 0.5 0.5
  children [
    Gyro {
    }
    InertialUnit {
    }
    Accelerometer {
    }
    Solid {
      children [
        Shape {
          appearance PBRAppearance {
            baseColor 0.643137 0 0
            normalMap ImageTexture {
              url [
                "/usr/local/webots/projects/appearances/protos/textures/carpet/carpet_pattern_normal.jpg"
              ]
            }
          }
          geometry Box {
            size 0.1 0.1 0.3
          }
        }
      ]
      name "solid(2)"
      boundingObject Shape {
        geometry Box {
          size 0.1 0.1 0.3
        }
      }
      physics Physics {
      }
    }
    HingeJoint {
      jointParameters HingeJointParameters {
        anchor 0.25 0 -0.1
      }
      device [
        RotationalMotor {
          name "wheel1"
        }
      ]
      endPoint Solid {
        translation 0.05000181310034463 -4.1496710374841135e-05 -0.09991161470515705
        rotation 0.018472153637126683 0.01826617511896317 -0.9996625062422467 1.570639742400216
        children [
          Shape {
            appearance PBRAppearance {
              baseColor 0 0 0
              roughness 1
              roughnessMap ImageTexture {
                url [
                  "textures/checkered_marble.jpg"
                ]
              }
              metalness 0
              normalMap ImageTexture {
                url [
                  "textures/checkered_marble.jpg"
                ]
              }
            }
            geometry Cylinder {
              height 0.01
              radius 0.075
            }
          }
        ]
        boundingObject Cylinder {
          height 0.01
          radius 0.075
        }
        physics Physics {
        }
      }
    }
    HingeJoint {
      jointParameters HingeJointParameters {
        anchor 0.25 -0.04 0.13
      }
      device [
        RotationalMotor {
          name "wheel3"
        }
      ]
      endPoint Solid {
        translation 0.04995520000000139 -0.04000459999999983 0.12882900000000003
        rotation 0.050045380606469625 0.0401930282540847 -0.9979378639773722 1.5781619964395666
        scale 0.5 0.5 0.5
        children [
          Shape {
            appearance PBRAppearance {
              baseColor 0 0 0
              roughness 1
              roughnessMap ImageTexture {
                url [
                  "textures/checkered_marble.jpg"
                ]
              }
              metalness 0
              normalMap ImageTexture {
                url [
                  "textures/checkered_marble.jpg"
                ]
              }
            }
            geometry Cylinder {
              height 0.01
              radius 0.075
            }
          }
        ]
        name "solid(3)"
        boundingObject Cylinder {
          height 0.01
          radius 0.075
        }
        physics Physics {
        }
      }
    }
    HingeJoint {
      jointParameters HingeJointParameters {
        anchor 0.25 -0.04 0.13
      }
      device [
        RotationalMotor {
          name "wheel4"
        }
      ]
      endPoint Solid {
        translation -0.050010599999994354 -0.03991869999999996 0.130872
        rotation -0.018468458158205914 -0.018707967675872586 -0.999654404281148 1.5716131308964774
        scale 0.5 0.5 0.5
        children [
          Shape {
            appearance PBRAppearance {
              baseColor 0 0 0
              roughness 1
              roughnessMap ImageTexture {
                url [
                  "textures/checkered_marble.jpg"
                ]
              }
              metalness 0
              normalMap ImageTexture {
                url [
                  "textures/checkered_marble.jpg"
                ]
              }
            }
            geometry Cylinder {
              height 0.01
              radius 0.075
            }
          }
        ]
        name "solid(4)"
        boundingObject Cylinder {
          height 0.01
          radius 0.075
        }
        physics Physics {
        }
      }
    }
    HingeJoint {
      jointParameters HingeJointParameters {
        anchor -0.25 0 -0.1
      }
      device [
        RotationalMotor {
          name "wheel2"
        }
      ]
      endPoint Solid {
        translation -0.0499997034279365 -5.041360322595632e-05 -0.10008309666200127
        rotation -0.018468453576496898 -0.018707914535196435 -0.9996544053602908 1.5716133906004126
        children [
          Shape {
            appearance PBRAppearance {
              baseColor 0 0 0
              roughness 1
              metalness 0
              normalMap ImageTexture {
                url [
                  "textures/checkered_marble.jpg"
                ]
              }
            }
            geometry Cylinder {
              height 0.01
              radius 0.075
            }
          }
        ]
        name "solid(1)"
        boundingObject Cylinder {
          height 0.01
          radius 0.075
        }
        physics Physics {
        }
      }
    }
  ]
  boundingObject Shape {
    geometry Box {
      size 0.1 0.1 0.1
    }
  }
  physics Physics {
  }
  controller "sensorsAndStuff"
}
