#VRML_SIM R2021a utf8
WorldInfo {
  coordinateSystem "NUE"
}
Viewpoint {
  orientation 0.00386660301177966 0.9978637448417229 0.06521499913058597 3.1665198932434717
  position -0.0028842899558671024 0.051579192101058394 -0.5585961492680611
}
TexturedBackground {
}
TexturedBackgroundLight {
}
RectangleArena {
}
Robot {
  translation 0 0.06 -0.08
  scale 0.5 0.5 0.5
  children [
    Gyro {
    }
    InertialUnit {
    }
    Accelerometer {
    }
    Solid {
      children [
        Shape {
          appearance PBRAppearance {
            baseColor 0.643137 0 0
            normalMap ImageTexture {
              url [
                "/usr/local/webots/projects/appearances/protos/textures/carpet/carpet_pattern_normal.jpg"
              ]
            }
          }
          geometry Box {
            size 0.1 0.1 0.3
          }
        }
      ]
      name "solid(2)"
      boundingObject Shape {
        geometry Box {
          size 0.1 0.1 0.3
        }
      }
      physics Physics {
      }
    }
    HingeJoint {
      jointParameters HingeJointParameters {
        anchor 0.25 0 -0.1
      }
      device [
        RotationalMotor {
          name "wheel1"
        }
      ]
      endPoint Solid {
        translation 0.050001813100348236 -4.149671037482519e-05 -0.09991161470515705
        rotation 0.018472153637120885 0.018266175118963737 -0.9996625062422467 1.570639742400196
        children [
          Shape {
            appearance PBRAppearance {
              baseColor 0 0 0
              roughness 1
              roughnessMap ImageTexture {
                url [
                  "textures/checkered_marble.jpg"
                ]
              }
              metalness 0
              normalMap ImageTexture {
                url [
                  "textures/checkered_marble.jpg"
                ]
              }
            }
            geometry Cylinder {
              height 0.01
              radius 0.075
            }
          }
        ]
        boundingObject Cylinder {
          height 0.01
          radius 0.075
        }
        physics Physics {
        }
      }
    }
    HingeJoint {
      jointParameters HingeJointParameters {
        anchor 0.25 -0.04 0.13
      }
      device [
        RotationalMotor {
          name "wheel3"
        }
      ]
      endPoint Solid {
        translation 0.04995520000000345 -0.040004599999999974 0.12882900000000005
        rotation 0.050045380606469 0.04019302825408343 -0.997937863977372 1.5781619964395597
        scale 0.5 0.5 0.5
        children [
          Shape {
            appearance PBRAppearance {
              baseColor 0 0 0
              roughness 1
              roughnessMap ImageTexture {
                url [
                  "textures/checkered_marble.jpg"
                ]
              }
              metalness 0
              normalMap ImageTexture {
                url [
                  "textures/checkered_marble.jpg"
                ]
              }
            }
            geometry Cylinder {
              height 0.01
              radius 0.075
            }
          }
        ]
        name "solid(3)"
        boundingObject Cylinder {
          height 0.01
          radius 0.075
        }
        physics Physics {
        }
      }
    }
    HingeJoint {
      jointParameters HingeJointParameters {
        anchor 0.25 -0.04 0.13
      }
      device [
        RotationalMotor {
          name "wheel4"
        }
      ]
      endPoint Solid {
        translation -0.05001059999998603 -0.03991870000000007 0.13087199999999996
        rotation -0.018468458158204297 -0.018707967675870216 -0.999654404281148 1.57161313089645
        scale 0.5 0.5 0.5
        children [
          Shape {
            appearance PBRAppearance {
              baseColor 0 0 0
              roughness 1
              roughnessMap ImageTexture {
                url [
                  "textures/checkered_marble.jpg"
                ]
              }
              metalness 0
              normalMap ImageTexture {
                url [
                  "textures/checkered_marble.jpg"
                ]
              }
            }
            geometry Cylinder {
              height 0.01
              radius 0.075
            }
          }
        ]
        name "solid(4)"
        boundingObject Cylinder {
          height 0.01
          radius 0.075
        }
        physics Physics {
        }
      }
    }
    HingeJoint {
      jointParameters HingeJointParameters {
        anchor -0.25 0 -0.1
      }
      device [
        RotationalMotor {
          name "wheel2"
        }
      ]
      endPoint Solid {
        translation -0.04999970342793955 -5.041360322601244e-05 -0.10008309666200127
        rotation -0.018468453576498577 -0.0187079145351976 -0.9996544053602908 1.5716133906003662
        children [
          Shape {
            appearance PBRAppearance {
              baseColor 0 0 0
              roughness 1
              metalness 0
              normalMap ImageTexture {
                url [
                  "textures/checkered_marble.jpg"
                ]
              }
            }
            geometry Cylinder {
              height 0.01
              radius 0.075
            }
          }
        ]
        name "solid(1)"
        boundingObject Cylinder {
          height 0.01
          radius 0.075
        }
        physics Physics {
        }
      }
    }
  ]
  boundingObject Shape {
    geometry Box {
      size 0.1 0.1 0.1
    }
  }
  physics Physics {
  }
  controller "sensorsAndStuff"
}
